<?xml version="1.0" ?>
  <robot name="bot" xmlns:xacro="http://ros.org/wiki/xacro">

  <xacro:include filename="bot_ros2_control.xacro" />


  <link name="base_footprint">
  </link>
    
  <joint name="base_joint" type="fixed">
    <parent link="base_footprint"/>
    <child link="base_link"/>
    <origin xyz="0.0 0.0 0.15" rpy="0.0 0.0 3.14159"/>  
  </joint>

<link name="base_link">
  <visual>
    <geometry>
      <box size="0.8 0.7 0.2"/>
    </geometry>
    <material name="gray">
      <color rgba="0.2 0.2 0.2 1" />
    </material>
  </visual>

  <collision>
    <geometry>
      <box size="0.8 0.7 0.2"/>
    </geometry>
  </collision>

  <inertial>
    <mass value="2"/>
    <inertia ixx="0.0883" ixy="0.0" ixz="0.0" 
             iyy="0.1133" iyz="0.0" izz="0.187"/>
  </inertial>
</link>


  <link name="wheel_front_right">
  <inertial>
    <mass value="0.5"/>  <!-- OK for small wheels -->
    <inertia 
      ixx="0.00025" ixy="0.0" ixz="0.0"
      iyy="0.00025" iyz="0.0"
      izz="0.0001"/>
  </inertial>

  <visual>
    <geometry>
      <cylinder radius="0.10" length="0.05"/>
    </geometry>
    <material name="white">
      <color rgba="1 1 1 1"/>
    </material>
  </visual>

  <collision>
    <geometry>
      <cylinder radius="0.10" length="0.05"/>
    </geometry>
  </collision>
  </link>

  <link name="wheel_front_left">
  <inertial>
    <mass value="0.5"/>  <!-- OK for small wheels -->
    <inertia 
      ixx="0.00025" ixy="0.0" ixz="0.0"
      iyy="0.00025" iyz="0.0"
      izz="0.0001"/>
  </inertial>

  <visual>
    <geometry>
      <cylinder radius="0.10" length="0.05"/>
    </geometry>
    <material name="white">
      <color rgba="1 1 1 1"/>
    </material>
  </visual>

  <collision>
    <geometry>
      <cylinder radius="0.10" length="0.05"/>
    </geometry>
  </collision>
  </link>

<link name="wheel_back_right">
  <inertial>
    <mass value="0.5"/>  <!-- OK for small wheels -->
    <inertia 
      ixx="0.00025" ixy="0.0" ixz="0.0"
      iyy="0.00025" iyz="0.0"
      izz="0.0001"/>
  </inertial>

  <visual>
    <geometry>
      <cylinder radius="0.10" length="0.05"/>
    </geometry>
    <material name="white">
      <color rgba="1 1 1 1"/>
    </material>
  </visual>

  <collision>
    <geometry>
      <cylinder radius="0.10" length="0.05"/>
    </geometry>
  </collision>
  </link>

<link name="wheel_back_left">
  <inertial>
    <mass value="0.5"/> 
    <inertia 
      ixx="0.00025" ixy="0.0" ixz="0.0"
      iyy="0.00025" iyz="0.0"
      izz="0.0001"/>
  </inertial>

  <visual>
    <geometry>
      <cylinder radius="0.10" length="0.05"/>
    </geometry>
    <material name="white">
      <color rgba="1 1 1 1"/>
    </material>
  </visual>

  <collision>
    <geometry>
      <cylinder radius="0.10" length="0.05"/>
    </geometry>
  </collision>
</link>




  <link name="rgb_camera">
    <inertial>
            <mass value="0.05" />
            <inertia ixx="0.01" ixy="0.0" ixz="0" 
            iyy="0.01" iyz="0" izz="0.01" />
    </inertial>

    <visual>
      
      <geometry>
        <box size="0.1 0.1 0.1"/>
      </geometry>
      <material name="blue">
        <color rgba="0 0 1 1"/>
      </material>
    </visual>    <origin xyz="-0.35 0 0.15" rpy="0 0.0 3.14"/>


    <collision>
      <geometry>
          <box size="0.1 0.5 0.2"/>
      </geometry>
    </collision>
  </link>

  <joint name="camera_joint" type="fixed">
    <origin xyz="-0.43 0 0.0" rpy="0 0.0 3.14"/>
    <parent link="base_link"/>
    <child link="rgb_camera"/>
    <axis xyz="0.0 0 0"/>

  </joint>

  <joint type="fixed" name="camera_optical_joint">
    <origin xyz="0 0 0" rpy="-1.5707 0 -1.5707"/>
    <child link="camera_link_optical"/>
    <parent link="rgb_camera"/>
  </joint>

  <link name="camera_link_optical">
  </link>

    <gazebo reference="rgb_camera">
    <sensor name="camera" type="camera">
      <camera>
        <horizontal_fov>1.3962634</horizontal_fov>
        <image>
          <width>640</width>
          <height>480</height>
          <format>R8G8B8</format>
        </image>
        <clip>
          <near>0.1</near>
          <far>15</far>
        </clip>
        <noise>
          <type>gaussian</type>
          <mean>0.0</mean>
          <stddev>0.007</stddev>
        </noise>
        <optical_frame_id>camera_link_optical</optical_frame_id>
        <camera_info_topic>camera/camera_info</camera_info_topic>
      </camera>
      <always_on>1</always_on>
      <update_rate>20</update_rate>
      <visualize>true</visualize>
      <topic>camera/image_raw</topic>
    </sensor>
    </gazebo>


  <link name="laser_link">
    <inertial>
            <mass value="0.5" />
            <inertia ixx="0.01" ixy="0.0" ixz="0" 
            iyy="0.01" iyz="0" izz="0.01" />
    </inertial>

    <visual>
      <geometry>
        <cylinder radius="0.1" length="0.1"/>
      </geometry>
      <material name="red">
        <color rgba="1 0 0  1"/>
      </material>
    </visual>

    <collision>
      <geometry>
        <cylinder radius="0.1" length="0.1"/>
      </geometry>
    </collision>
  </link>

  <joint name="laser_joint" type="fixed">
    <origin xyz="0 0 0.15" rpy="0 0.0 3.14"/>
    <parent link="base_link"/>
    <child link="laser_link"/>
    <axis xyz="0.0 0.0 1.0"/>

  </joint>

    <!-- 2D LIDAR-->  
  <gazebo reference="laser_link">
    <sensor name="lidar" type="gpu_lidar">
      <always_on>true</always_on>
      <visualize>true</visualize>
      <topic>scan</topic>
      <update_rate>5</update_rate>
      <gz_frame_id>laser_link</gz_frame_id>
      <lidar>
        <scan>
          <horizontal>
            <samples>360</samples>
            <resolution>1.00000</resolution>
            <min_angle>0.000000</min_angle>
            <max_angle>6.280000</max_angle>
          </horizontal>
        </scan>
        <range>
          <min>0.120000</min>
          <max>12.0</max>
          <resolution>0.02</resolution>
        </range>
        <noise>
          <type>gaussian</type>
          <mean>0.0</mean>
          <stddev>0.01</stddev>
        </noise>
      </lidar>
    </sensor>
  </gazebo>

  <joint name="navsat_joint" type="fixed">
    <origin xyz="0 0 0" rpy="0 0 0" />
    <parent link="base_link"/>
    <child link="navsat_link" />
  </joint>

  <link name="navsat_link">
  </link>

  <joint name="imu_joint" type="fixed">
    <origin xyz="0 0 0" rpy="0 0 0" />
    <parent link="base_link"/>
    <child link="imu_link" />
  </joint>

  <link name="imu_link">
  </link>

  <gazebo reference="imu_link">
    <sensor name="imu" type="imu">
      <always_on>1</always_on>
      <update_rate>50</update_rate>
      <visualize>true</visualize>
      <topic>imu</topic>
      <enable_metrics>true</enable_metrics>
      <gz_frame_id>imu_link</gz_frame_id>
    </sensor>
  </gazebo>

  <gazebo reference="navsat_link">
    <sensor name="navsat" type="navsat">
      <always_on>1</always_on>
      <update_rate>1</update_rate>
      <topic>navsat</topic>
      <gz_frame_id>navsat_link</gz_frame_id>
    </sensor>
  </gazebo>

    <joint name="wheel_front_right_joint" type="continuous">
    <origin xyz="-0.25 0.4 -0.05" rpy="1.57 0.0 0.0"/>
    <parent link="base_link"/>
    <child link="wheel_front_right"/>
    <axis xyz="0.0 0.0 1.0"/>
  </joint>


  <joint name="wheel_front_left_joint" type="continuous">
    <origin xyz="-0.25 -0.4 -0.05" rpy="1.57 0.0 0.0"/>
    <parent link="base_link"/>
    <child link="wheel_front_left"/>
    <axis xyz="0.0 0.0 1.0"/>

  </joint>

    <joint name="wheel_back_right_joint" type="continuous">
    <origin xyz="0.25 0.4 -0.05" rpy="1.57 0.0 0.0"/>
    <parent link="base_link"/>
    <child link="wheel_back_right"/>
    <axis xyz="0.0 0.0 1.0"/>

  </joint>

  <joint name="wheel_back_left_joint" type="continuous">
    <origin xyz="0.25 -0.4 -0.05" rpy="1.57 0.0 0.0"/>
    <parent link="base_link"/>
    <child link="wheel_back_left"/>
    <axis xyz="0.0 0.0 1.0"/>

  </joint>

    <gazebo reference="wheel_front_right">
    <mu1>1.0</mu1>       
    <mu2>0.8</mu2>        
    <kp>100000.0</kp>     
    <kd>1.0</kd>           
    <minDepth>0.001</minDepth>   
    <maxVel>1</maxVel>         
    <fdir1>1 0 0</fdir1>     
    </gazebo>

    <gazebo reference="wheel_front_left">
    <mu1>1.0</mu1>       
    <mu2>0.8</mu2>        
    <kp>100000.0</kp>     
    <kd>1.0</kd>           
    <minDepth>0.001</minDepth>   
    <maxVel>1</maxVel>         
    <fdir1>1 0 0</fdir1>   
    </gazebo>

    <gazebo reference="wheel_back_right">
    <mu1>1.0</mu1>       
    <mu2>0.8</mu2>        
    <kp>100000.0</kp>     
    <kd>1.0</kd>           
    <minDepth>0.001</minDepth>   
    <maxVel>1</maxVel>         
    <fdir1>1 0 0</fdir1>   
    </gazebo>

    <gazebo reference="wheel_back_left">
    <mu1>1.0</mu1>       
    <mu2>0.8</mu2>          
    <kp>100000.0</kp>     
    <kd>1.0</kd>           
    <minDepth>0.001</minDepth>   
    <maxVel>1</maxVel>         
    <fdir1>1 0 0</fdir1>   
    </gazebo>

    <gazebo>
        <plugin filename="ign_ros2_control-system" name="ign_ros2_control::IgnitionROS2ControlPlugin">
          <parameters>$(find bot_controller)/config/bot_controller.yaml</parameters>
        </plugin>
        <plugin filename="ignition-gazebo-imu-system" name="ignition::gazebo::systems::Imu"></plugin>
        <plugin filename="ignition-gazebo-sensors-system" name="ignition::gazebo::systems::Sensors">
        <render_engine>ogre2</render_engine>
      </plugin>
        <plugin
        filename="ignition-gazebo-navsat-system"
        name="ignition::gazebo::systems::NavSat">
      </plugin>
    </gazebo>

</robot>